Workbook

Sheet Screening summary
A1: Soil spectral library review – screening summary
A4: Records
A5: Records in inventory | B5: =COUNTA(Papers!$B$2:$B$114) -> 113
A6: Excluded – duplicate | B6: =COUNTIF(Papers!$AO$2:$AO$114,"Exclude (duplicate)") -> 1
A7: Excluded – C1 not soil-specific | B7: =COUNTIFS(Papers!$AO$2:$AO$114,"Exclude",Papers!$AK$2:$AK$114,"No") -> 2
A8: Excluded – C2 not spectroscopy | B8: =COUNTIFS(Papers!$AO$2:$AO$114,"Exclude",Papers!$AK$2:$AK$114,"Yes",Papers!$AL$2:$AL$114,"No") -> 1
A9: Excluded – C3 no library-scale data | B9: =COUNTIFS(Papers!$AO$2:$AO$114,"Exclude",Papers!$AK$2:$AK$114,"Yes",Papers!$AL$2:$AL$114,"Yes",Papers!$AM$2:$AM$114,"No") -> 24
A10: Needs checking | B10: =COUNTIF(Papers!$AO$2:$AO$114,"Check") -> 1
A11: Included papers | B11: =COUNTIF(Papers!$AO$2:$AO$114,"Include") -> 84
A12: Check: all records accounted for | B12: =IF(B6+B7+B8+B9+B10+B11=B5,"OK","Mismatch") -> OK
A14: Included papers by role
A15: Introduces a library | B15: =COUNTIFS(Papers!$AO$2:$AO$114,"Include",Papers!$AQ$2:$AQ$114,"Introduces") -> 40
A16: Extends / updates a library | B16: =COUNTIFS(Papers!$AO$2:$AO$114,"Include",Papers!$AQ$2:$AQ$114,"Extends / updates") -> 2
A17: Methods for a library | B17: =COUNTIFS(Papers!$AO$2:$AO$114,"Include",Papers!$AQ$2:$AQ$114,"Methods for") -> 7
A18: Uses a library | B18: =COUNTIFS(Papers!$AO$2:$AO$114,"Include",Papers!$AQ$2:$AQ$114,"Uses") -> 35
A20: Libraries
A21: Distinct libraries | B21: =COUNTA(Libraries!$A$2:$A$56) -> 55
A22: … with their introducing paper in the review | B22: =COUNTIF(Libraries!$L$2:$L$56,"Yes") -> 40
A23: … introducing paper missing from the review | B23: =COUNTIF(Libraries!$L$2:$L$56,"No") -> 15 | C23: See Notes column in Libraries for candidate references
A24: Global | B24: =COUNTIF(Libraries!$C$2:$C$56,"Global") -> 7
A25: Continental / regional (countries not itemised) | B25: =COUNTIF(Libraries!$C$2:$C$56,"Continental / regional") -> 2
A26: Multi-country | B26: =COUNTIF(Libraries!$C$2:$C$56,"Multi-country") -> 4
A27: National | B27: =COUNTIF(Libraries!$C$2:$C$56,"National") -> 21
A28: Sub-national | B28: =COUNTIF(Libraries!$C$2:$C$56,"Sub-national") -> 21
A29: Libraries under 200 samples | B29: =COUNTIF(Libraries!$I$2:$I$56,"Yes") -> 4 | C29: Flagged, not excluded (no minimum-size rule applied)
A31: Countries
A32: Countries covered by at least one library | B32: =COUNTIF('Country coverage'!$C$2:$C$43,">0") -> 42
A33: … with a national library | B33: =COUNTIF('Country coverage'!$G$2:$G$43,"National") -> 15
A34: … sub-national only | B34: =COUNTIF('Country coverage'!$G$2:$G$43,"Sub-national only") -> 8
A35: … multi-country only | B35: =COUNTIF('Country coverage'!$G$2:$G$43,"Multi-country only") -> 19
A37: Screening criteria (coded in Papers, columns AK–AT)
A38: C1 Soil-specific | C38: Spectra are of soils (excludes general mineral/rock/vegetation libraries).
A39: C2 Spectroscopic | C39: The study measures or analyses soil spectra (any range: vis-NIR, MIR, LWIR).
A40: C3 Library-scale data | C40: Spectra come from, or are added to, an identifiable library spanning multiple fields/sites, or the authors present the dataset as a library. Single-field, single-site or trial studies with no library = No.
A41: Decision | C41: Include if C1–C3 are all Yes; Check if any is Check; Exclude otherwise; duplicates excluded first. Computed by formula – edit the yellow cells, not the decision.
A42: Paper role | C42: Introduces (first describes the library) · Extends / updates (new release, opening, service built on it) · Methods for (standardisation, harmonisation, QA of that library) · Uses (calibration/application).
A43: Minimum size | C43: None applied. Libraries under 200 samples are flagged in Libraries column I so a threshold can be set later.
A44: Unit of analysis | C44: Libraries, not papers. Country and scale statistics count distinct libraries (sheet Libraries), so heavily published libraries are counted once.
A45: Yellow cells | C45: Coding inputs. Change them and every decision, count and the coverage table update.

Sheet Papers
A1: Authors | B1: Title | C1: Year | D1: DOI | E1: Library Name | F1: Scale | G1: Country/Region | H1: Continent | I1: Number of Samples | J1: Soil Types | K1: Land Use | L1: Sampling Depth | M1: Sampling Strategy | N1: Spectral Region | O1: Wavelength Range (nm) | P1: Instrument | Q1: Spectral Resolution | R1: Sample Preparation | S1: Measurement Conditions | T1: Reference Soil Properties | U1: Laboratory Methods | V1: Spectral Preprocessing | W1: Feature Selection | X1: Modelling Method | Y1: Validation Method | Z1: Performance Metrics | AA1: QA/QC | AB1: Metadata Included | AC1: Data Availability | AD1: FAIR Compliance | AE1: Standardization Protocol | AF1: Harmonization Method | AG1: Main Applications | AH1: Main Challenges | AI1: Future Recommendations | AJ1: Key Findings | AK1: C1 Soil-specific | AL1: C2 Spectroscopic | AM1: C3 Library-scale data | AN1: Duplicate of row | AO1: Screening decision | AP1: Exclusion reason / notes | AQ1: Paper role | AR1: Library ID | AS1: Secondary library ID | AT1: Library name
A2: Reddy B.S.; Shwetha H.R. | B2: Integrating Soil Spectral Library and PRISMA Data to Estimate Soil Organic Carbon in Crop Lands | C2: 2024 | D2: 10.1109/LGRS.2024.3374824 | E2: - | F2: - | G2: - | H2: - | I2: - | J2: - | K2: - | L2: Topsoil (cropland) | M2: Synthesized soil spectral library developed under laboratory conditions, integrated with PRISMA hyperspectral data for local-scale SOC mapping in Indian croplands | N2: vis-NIR-SWIR (laboratory SSL + PRISMA imagery) | O2: ~400-2500 (PRISMA hyperspectral range) | P2: Laboratory spectroradiometer (synthesized SSL) + PRISMA spaceborne hyperspectral sensor | Q2: PRISMA ~10 nm hyperspectral bands | R2: Laboratory-synthesized/prepared samples | S2: Laboratory (SSL) and spaceborne (PRISMA) | T2: Soil organic carbon (SOC) | U2: Walkley-Black method (SOC) | V2: Not specified in available sources | W2: Not specified in available sources | X2: Machine learning (ML) algorithms integrating synthesized SSL with PRISMA data | Y2: Local-scale validation of SOC estimation | Z2: R2/RMSE (not further specified in available sources) | AA2: Not specified in available sources | AB2: Cropland location, sensor type | AC2: Restricted (study dataset); PRISMA products (c)ASI | AD2: Partial | AE2: Not specified in available sources | AF2: Bridging synthesized laboratory SSL with spaceborne hyperspectral data via ML | AG2: Local-scale cropland SOC mapping for food security (SDG 2) in developing nations | AH2: Inconsistent calibration libraries and impractical regular sample collection between crop rotations in agriculture-predominant countries like India | AI2: Use laboratory-synthesized SSLs fused with hyperspectral (PRISMA) data to overcome sample-collection constraints in developing nations | AJ2: To overcome impractical repeated soil sampling in Indian croplands, this study developed a laboratory-synthesized soil spectral library and fused it with PRISMA hyperspectral data using machine learning, bridging the gap between synthesized SSL and satellite data for local-scale SOC mapping in support of food security. | AK2: Yes | AL2: Yes | AM2: Yes | AO2: =IF(AN2<>"","Exclude (duplicate)",IF(OR(AK2="Check",AL2="Check",AM2="Check"),"Check",IF(AND(AK2="Yes",AL2="Yes",AM2="Yes"),"Include","Exclude"))) -> Include | AQ2: Introduces | AR2: IN-PRISMA | AT2: =IF(AR2="","",IFERROR(INDEX(Libraries!$B:$B,MATCH(AR2,Libraries!$A:$A,0)),"ID not found")) -> Laboratory-synthesised cropland SSL (India)
A3: Clingensmith C.M.; Grunwald S. | B3: Transferring and Spiking of VNIR Models for Soil Property Predictions in Southern India | C3: 2025 | D3: 10.1080/00103624.2025.2522188 | E3: - | F3: - | G3: Southern India | H3: Asia | I3: - | J3: - | K3: - | AK3: Yes | AL3: Yes | AM3: Yes | AO3: =IF(AN3<>"","Exclude (duplicate)",IF(OR(AK3="Check",AL3="Check",AM3="Check"),"Check",IF(AND(AK3="Yes",AL3="Yes",AM3="Yes"),"Include","Exclude"))) -> Include | AP3: Assumed KSSL vis-NIR models transferred to India – check | AQ3: Uses | AR3: US-KSSL-VNIR | AT3: =IF(AR3="","",IFERROR(INDEX(Libraries!$B:$B,MATCH(AR3,Libraries!$A:$A,0)),"ID not found")) -> USDA NSSC-KSSL vis-NIR library
A4: Clairotte M.; Grinand C.; Kouakoua E.; Thébault A.; Saby N.P.A.; Bernoux M.; Barthès B.G. | B4: National calibration of soil organic carbon concentration using diffuse infrared reflectance spectroscopy | C4: 2016 | D4: 10.1016/j.geoderma.2016.04.021 | E4: - | F4: National | G4: France | H4: Europe | I4: - | J4: - | K4: - | AK4: Yes | AL4: Yes | AM4: Yes | AO4: =IF(AN4<>"","Exclude (duplicate)",IF(OR(AK4="Check",AL4="Check",AM4="Check"),"Check",IF(AND(AK4="Yes",AL4="Yes",AM4="Yes"),"Include","Exclude"))) -> Include | AQ4: Introduces | AR4: FR-RMQS-IR | AT4: =IF(AR4="","",IFERROR(INDEX(Libraries!$B:$B,MATCH(AR4,Libraries!$A:$A,0)),"ID not found")) -> French RMQS NIR/MIR national library
A5: Paiva A.F.D.S.; Poppiel R.R.; Rosin N.A.; Greschuk L.T.; Rosas J.T.F.; Demattê J.A.M. | B5: The Brazilian Program of soil analysis via spectroscopy (ProBASE): Combining spectroscopy and wet laboratories to understand new technologies | C5: 2022 | D5: 10.1016/j.geoderma.2022.115905 | E5: BSSL | F5: National | G5: Brazil | H5: South America | I5: ~7000 | J5: Brazilian agricultural soils | K5: Agriculture | AK5: Yes | AL5: Yes | AM5: Yes | AO5: =IF(AN5<>"","Exclude (duplicate)",IF(OR(AK5="Check",AL5="Check",AM5="Check"),"Check",IF(AND(AK5="Yes",AL5="Yes",AM5="Yes"),"Include","Exclude"))) -> Include | AQ5: Uses | AR5: BR-BSSL | AT5: =IF(AR5="","",IFERROR(INDEX(Libraries!$B:$B,MATCH(AR5,Libraries!$A:$A,0)),"ID not found")) -> Brazilian Soil Spectral Library (BSSL, vis-NIR-SWIR)
A6: Poppiel R.R.; Paiva A.F.D.S.; Demattê J.A.M. | B6: Bridging the gap between soil spectroscopy and traditional laboratory: Insights for routine implementation | C6: 2022 | D6: 10.1016/j.geoderma.2022.116029 | E6: Brazilian Soil Spectral Library (BSSL) | F6: Regional | G6: Brazil | H6: South America | I6: ~7200 | J6: Ferralsols, Acrisols, Lixisols, Cambisols, Arenosols, Plinthosols, Nitisols | K6: Agricultural | L6: Not specified in available sources | M6: Samples from 36 commercial laboratories in Brazil and Paraguay; spectra-based systematic sampling for subset selection | N6: vis-NIR-SWIR (BSSL-based) | O6: 350-2500 | P6: ASD FieldSpec-type spectroradiometer | Q6: Not specified in available sources | R6: Air-dried, ground, sieved (routine commercial lab prep) | S6: Laboratory (commercial analytical labs) | T6: Routine fertility/analytical properties (commercial lab suite) | U6: Standard commercial soil testing methods | V6: Not specified in available sources | W6: Spectral clustering to detect outlying attributes, adjusted to data distribution | X6: Spectra-based systematic sampling combined with BSSL calibration models | Y6: Comparison of spectroscopy-based vs traditional wet-chemistry results across 36 labs | Z6: ~25% of labs had potential to reduce need for lab analysis by at least 50% | AA6: Internal quality control via spectral clustering/outlier detection; analytical quality assessment across labs | AB6: Laboratory identity, country (Brazil/Paraguay), attribute distributions | AC6: Restricted (commercial lab data, BSSL-linked) | AD6: Partial | AE6: Recommends standards/protocols for routine lab uptake of spectroscopy | AF6: Spectra-based systematic sampling to equally distribute attributes among calibration subsets | AG6: Bridging soil spectroscopy into routine commercial soil-testing laboratory workflows | AH6: Lack of standards/protocols, spectral libraries, chemometrics capacity, and trained professionals in routine labs | AI6: Develop standards/protocols, expand spectral libraries, and build chemometrics capacity/professional training for routine lab adoption | AJ6: Analyzing 36 commercial labs in Brazil and Paraguay, this study found nearly 25% could cut wet-chemistry lab analysis needs by at least half using soil spectroscopy, but broader adoption is limited by a lack of standards, protocols, spectral libraries, and chemometrics expertise in routine labs. | AK6: Yes | AL6: Yes | AM6: Yes | AO6: =IF(AN6<>"","Exclude (duplicate)",IF(OR(AK6="Check",AL6="Check",AM6="Check"),"Check",IF(AND(AK6="Yes",AL6="Yes",AM6="Yes"),"Include","Exclude"))) -> Include | AQ6: Uses | AR6: BR-BSSL | AT6: =IF(AR6="","",IFERROR(INDEX(Libraries!$B:$B,MATCH(AR6,Libraries!$A:$A,0)),"ID not found")) -> Brazilian Soil Spectral Library (BSSL, vis-NIR-SWIR)
A7: Leenen M.; Pätzold S.; Tóth G.; Welp G. | B7: A LUCAS-based mid-infrared soil spectral library: Its usefulness for soil survey and precision agriculture | C7: 2022 | D7: 10.1002/jpln.202100031 | E7: LUCAS | F7: Continental | G7: Belgium, Luxembourg, Germany, Netherlands | H7: Europe | I7: 1013 | J7: Cambisols, Stagnosols, Luvisols, Chernozems, Regosols, Arenosols, Retisols | K7: Agricultural/Arable | L7: Topsoil (arable) | M7: LUCAS 2009 survey samples subset (Belgium, Netherlands, Luxembourg, Germany) | N7: MIR (mid-infrared) | O7: Mid-infrared range (typically ~2500-15000 nm / 4000-650 cm-1) | P7: FTIR bench-top spectrometer | Q7: Not specified in detail | R7: Air-dried, sieved, ground topsoil | S7: Laboratory | T7: Clay content and other soil properties (texture, nutrients) | U7: Standard wet-chemistry reference methods (LUCAS protocol) | V7: Not detailed | W7: None specified | X7: Partial Least Squares Regression (PLSR); generic and parent-material-stratified models | Y7: Leave-one-out cross-validation (LOOCV) | Z7: R2 (e.g. ~0.89, 0.85, 0.88 for clay prediction across models) | AA7: Stratification by parent material to reduce error | AB7: Parent material, land use, location | AC7: Restricted (subset of LUCAS) | AD7: Partial | AE7: LUCAS survey protocol | AF7: Stratification by parent material for local calibration | AG7: Soil survey at regional scale and precision agriculture at field scale | AH7: Transferability of generic models to field-scale precision agriculture applications | AI7: Further stratification and local calibration to improve field-scale applicability | AJ7: A 1,013-sample MIR library built from LUCAS topsoil data across four countries achieved strong clay-content prediction (R2 up to ~0.89) and shows promise for both regional soil survey and precision agriculture use. | AK7: Yes | AL7: Yes | AM7: Yes | AO7: =IF(AN7<>"","Exclude (duplicate)",IF(OR(AK7="Check",AL7="Check",AM7="Check"),"Check",IF(AND(AK7="Yes",AL7="Yes",AM7="Yes"),"Include","Exclude"))) -> Include | AQ7: Introduces | AR7: EU-LUCAS-MIR4 | AT7: =IF(AR7="","",IFERROR(INDEX(Libraries!$B:$B,MATCH(AR7,Libraries!$A:$A,0)),"ID not found")) -> LUCAS-based MIR library (BE/LU/DE/NL)
A8: Gao S.; Li X.; Ding J.; Li B.; Wu X.; Tian J.; Ge X.; Zhu C.; Wang J.; Zhang Z. | B8: Unveiling the Advantages of UV−Vis/NIR−pXRF Data Fusion for Precise Estimation of Soil Heavy Metals in Farmland | C8: 2026 | D8: 10.1002/ldr.70488 | E8: - | F8: Local | G8: Xinjiang, China | H8: Asia | I8: 110 | J8: Agriculture soils | K8: Agricultural, grassland, and forest | AK8: Yes | AL8: Yes | AM8: No | AO8: =IF(AN8<>"","Exclude (duplicate)",IF(OR(AK8="Check",AL8="Check",AM8="Check"),"Check",IF(AND(AK8="Yes",AL8="Yes",AM8="Yes"),"Include","Exclude"))) -> Exclude | AP8: Local study (110 samples), no library | AQ8: — | AT8: =IF(AR8="","",IFERROR(INDEX(Libraries!$B:$B,MATCH(AR8,Libraries!$A:$A,0)),"ID not found"))
A9: Ma Y.; Roudier P.; Kumar K.; Palmada T.; Grealish G.; Carrick S.; Lilburne L.; Triantafilis J. | B9: A soil spectral library of New Zealand | C9: 2023 | D9: 10.1016/j.geodrs.2023.e00726 | E9: New Zealand Soil Classification (NZSC) | F9: National | G9: New Zealand | H9: Oceania | I9: 11246 | J9: All 14 NZSC orders: Allophanic, Brown, Gley, Granular, Melanic, Organic, Oxidic, Pallic, Podzols, Pumice, Raw, Recent, Semi-arid, Ultic | K9: Agricultural/Arable and Forest | L9: Topsoil (0-15/0-30 cm typical NZ survey depths) | M9: National compilation across all 14 NZSC soil orders | N9: vis-NIR and MIR | O9: vis-NIR 350-2500; MIR 2500-25000 | P9: ASD FieldSpec-type (vis-NIR) and FTIR (MIR) spectrometers | Q9: Not specified in available sources | R9: Air-dried, ground, sieved | S9: Laboratory | T9: Wide range: texture, SOC, minerals (iron oxides), fertility properties | U9: Standard NZ soil reference methods | V9: Not specified in available sources | W9: Not specified in available sources | X9: PLSR | Y9: Cross-validation | Z9: R2 (property-dependent) | AA9: Not specified in available sources | AB9: NZSC soil order, location, land use | AC9: Restricted/institutional (Manaaki Whenua/Landcare Research) | AD9: Partial | AE9: Not specified in available sources | AF9: Compilation across historical NZ soil surveys | AG9: National soil classification, mineral identification, property prediction | AH9: Combining legacy data collected under varying protocols | AI9: Continued harmonization and expansion of national coverage | AJ9: First comprehensive national soil spectral library for New Zealand spanning all 14 NZSC soil orders, enabling vis-NIR/MIR-based classification and property prediction across highly diverse volcanic, pastoral, and forest soils. | AK9: Yes | AL9: Yes | AM9: Yes | AO9: =IF(AN9<>"","Exclude (duplicate)",IF(OR(AK9="Check",AL9="Check",AM9="Check"),"Check",IF(AND(AK9="Yes",AL9="Yes",AM9="Yes"),"Include","Exclude"))) -> Include | AQ9: Introduces | AR9: NZ-SSL | AT9: =IF(AR9="","",IFERROR(INDEX(Libraries!$B:$B,MATCH(AR9,Libraries!$A:$A,0)),"ID not found")) -> New Zealand soil spectral library
A10: Moloney J.P.; Ma Y.; Stockmann U.; Manu V.T.; Minoneti V.; Hui S.T.; Halavatau S.M.; Patolo S.; Tukia T.; Foliaki S.; Carter T.; Macdonald B.C.T.; Barringer J.; Roudier P. | B10: Rapid soil attribute evaluation for soil security assessments in data-poor environments in the Pacific region | C10: 2024 | D10: 10.1016/j.soisec.2024.100161 | E10: New Zealand vis-NIR soil spectral library | F10: Local | G10: Tonga, New Zealand | H10: Oceania | I10: 11246 | J10: Allophanic soils and Coastal coral sands | K10: Diverse/Agricultural | AK10: Yes | AL10: Yes | AM10: Yes | AO10: =IF(AN10<>"","Exclude (duplicate)",IF(OR(AK10="Check",AL10="Check",AM10="Check"),"Check",IF(AND(AK10="Yes",AL10="Yes",AM10="Yes"),"Include","Exclude"))) -> Include | AQ10: Uses | AR10: NZ-SSL | AT10: =IF(AR10="","",IFERROR(INDEX(Libraries!$B:$B,MATCH(AR10,Libraries!$A:$A,0)),"ID not found")) -> New Zealand soil spectral library
A11: Nocita M.; Kooistra L.; Bachmann M.; Müller A.; Powell M.; Weel S. | B11: Predictions of soil surface and topsoil organic carbon content through the use of laboratory and field spectroscopy in the Albany Thicket Biome of Eastern Cape Province of South Africa | C11: 2011 | D11: 10.1016/j.geoderma.2011.09.018 | E11: - | F11: Local | G11: Albany Thicket Biome, South Africa | H11: Africa | I11: 113 | J11: Subtropical thicket vegetation soils | K11: Subtropical thicket and open savannah | AK11: Yes | AL11: Yes | AM11: No | AO11: =IF(AN11<>"","Exclude (duplicate)",IF(OR(AK11="Check",AL11="Check",AM11="Check"),"Check",IF(AND(AK11="Yes",AL11="Yes",AM11="Yes"),"Include","Exclude"))) -> Exclude | AP11: Local calibration study (113 samples), no library | AQ11: — | AT11: =IF(AR11="","",IFERROR(INDEX(Libraries!$B:$B,MATCH(AR11,Libraries!$A:$A,0)),"ID not found"))
A12: Francos N.; Ben-Dor E. | B12: A transfer function to predict soil surface reflectance from laboratory soil spectral libraries | C12: 2022 | D12: 10.1016/j.geoderma.2021.115432 | E12: - | F12: Local | G12: Israel, Italy, Greece | H12: Asia/Europe | I12: 115 | J12: Alluvial, Leptosol, Ferrosol, Fluvisol, Cambisol | K12: Agricultural | L12: Surface | M12: Local samples from Israel, Italy, Greece used to build transfer function between lab and field reflectance | N12: vis-NIR-SWIR | O12: 350-2500 | P12: ASD FieldSpec-type (lab) and field spectroradiometer | Q12: Not specified in available sources | R12: Laboratory: air-dried, sieved; Field: undisturbed surface | S12: Both laboratory and field | T12: Soil surface reflectance; water infiltration rate (surface-dependent property) | U12: Standard reference methods for surface property assessment | V12: Not specified in available sources | W12: None specified | X12: Transfer function (TF) between laboratory and field spectral levels | Y12: Cross-validation between predicted and measured field reflectance | Z12: Improved spectral assessment accuracy of surface-dependent property (not further specified) | AA12: Internal Soil Standard (ISS) used as reference | AB12: Site, soil type | AC12: Restricted | AD12: Partial | AE12: ISS (Lucky Bay) protocol basis | AF12: Transfer function linking laboratory spectral libraries to field surface reflectance | AG12: Predicting field/in-situ soil surface reflectance from existing laboratory spectral libraries | AH12: Laboratory spectra do not directly represent field surface conditions (roughness, moisture, crusting) | AI12: Extend transfer function approach to more regions/soil types and additional surface-dependent properties | AJ12: A transfer function developed between laboratory and field spectral measurements enabled existing laboratory SSLs to predict field-level soil surface reflectance and a surface-dependent property (water infiltration) across three Mediterranean countries. | AK12: Yes | AL12: Yes | AM12: No | AO12: =IF(AN12<>"","Exclude (duplicate)",IF(OR(AK12="Check",AL12="Check",AM12="Check"),"Check",IF(AND(AK12="Yes",AL12="Yes",AM12="Yes"),"Include","Exclude"))) -> Exclude | AP12: Transfer-function method; own 115 samples, no identifiable library | AQ12: — | AT12: =IF(AR12="","",IFERROR(INDEX(Libraries!$B:$B,MATCH(AR12,Libraries!$A:$A,0)),"ID not found"))
A13: Daempfling H.L.C.; Milewski R.; Notesco G.; Ben-Dor E.; Chabrillat S. | B13: Advancing Hyperspectral LWIR Imaging of Soils with a Controlled Laboratory Setup | C13: 2025 | D13: 10.3390/rs17233926 | E13: Legacy soil spectral library of Tel-Aviv University (Israel) | F13: National | G13: Israel | H13: Asia | I13: 12 | J13: Rhodoxeralf, Haploxeroll, Xerert, Calciorthid, Torriorthent, Haplargid | K13: Agricultural/Arid | L13: Surface soil samples (Tel-Aviv University legacy library subset) | M13: 12 variable soil samples selected from Israeli legacy SSL for controlled LWIR imaging | N13: LWIR (longwave/thermal infrared) | O13: ~8000-12000 (Telops Hyper-Cam LW range) | P13: Telops Hyper-Cam LW (Fourier-transform hyperspectral LWIR imaging spectrometer) | Q13: Per Hyper-Cam LW sensor specification (FTIR-based) | R13: Air-dried soils placed on heating plate with gold reference plate | S13: Controlled indoor laboratory setup, replicating airborne/spaceborne LWIR passive emissivity measurement | T13: Mineral composition (quartz, clay minerals, carbonates); organic carbon (Walkley-Black) | U13: XRD mineralogy; Walkley-Black organic carbon | V13: Spatial Averaging Before Blackbody Fitting (SABBF) method | W13: None specified | X13: Semi-quantitative mineral estimation from emissivity spectra | Y13: Comparison of lab emissivity results with outdoor Hyper-Cam LW measurements and XRD mineralogy | Z13: Good agreement between lab and outdoor LWIR spectra and XRD-based mineralogy (qualitative) | AA13: Rigorous calibration protocols; blackbody fitting-based temperature/emissivity retrieval | AB13: Soil type (e.g. Torriorthent), sample ID | AC13: Restricted (Tel-Aviv University legacy library subset) | AD13: Partial | AE13: Custom controlled laboratory LWIR protocol (calibration plate, SABBF) | AF13: Designed to bridge laboratory measurements and remote sensing (airborne/spaceborne) LWIR observations | AG13: Weather-independent laboratory-based mineral characterization via LWIR imaging spectroscopy | AH13: Achieving accurate indirect-emissivity retrieval indoors without natural downwelling radiance | AI13: Apply controlled LWIR laboratory setup more broadly to support airborne/spaceborne LWIR soil mineral mapping missions | AJ13: A new controlled laboratory LWIR hyperspectral imaging setup (Telops Hyper-Cam LW with SABBF processing) produced soil emissivity spectra that agreed well with outdoor measurements and XRD mineralogy, enabling weather-independent semi-quantitative soil mineral characterization. | AK13: Yes | AL13: Yes | AM13: Yes | AO13: =IF(AN13<>"","Exclude (duplicate)",IF(OR(AK13="Check",AL13="Check",AM13="Check"),"Check",IF(AND(AK13="Yes",AL13="Yes",AM13="Yes"),"Include","Exclude"))) -> Include | AP13: Uses 12 samples from the TAU legacy library for LWIR imaging | AQ13: Methods for | AR13: IL-TAU | AT13: =IF(AR13="","",IFERROR(INDEX(Libraries!$B:$B,MATCH(AR13,Libraries!$A:$A,0)),"ID not found")) -> Tel Aviv University legacy soil spectral library
A14: Bartholomeus H.; Schaepman-Strub G.; Blok D.; Sofronov R.; Udaltsov S. | B14: Spectral estimation of soil properties in siberian tundra soils and relations with plant species composition | C14: 2012 | D14: 10.1155/2012/241535 | E14: - | F14: Regional | G14: Siberia, Russia | H14: Asia | I14: 128 | J14: Organic and mineral tundra soils | K14: Nature (Shrub, Sedges) | AK14: Yes | AL14: Yes | AM14: No | AO14: =IF(AN14<>"","Exclude (duplicate)",IF(OR(AK14="Check",AL14="Check",AM14="Check"),"Check",IF(AND(AK14="Yes",AL14="Yes",AM14="Yes"),"Include","Exclude"))) -> Exclude | AP14: Local tundra study (128 samples), no library | AQ14: — | AT14: =IF(AR14="","",IFERROR(INDEX(Libraries!$B:$B,MATCH(AR14,Libraries!$A:$A,0)),"ID not found"))
A15: Cambule A.H.; Rossiter D.G.; Stoorvogel J.J.; Smaling E.M.A. | B15: Building a near infrared spectral library for soil organic carbon estimation in the Limpopo National Park, Mozambique | C15: 2012 | D15: 10.1016/j.geoderma.2012.03.011 | E15: Limpopo National Park (LNP) SSL | F15: Regional | G15: Mozambique | H15: Africa | I15: 129 | J15: Arenosols, Haplic Luvisols, Ferralic Arenosols, Eutric Fluvisols, Eutric Leptosols | K15: Conservation Area, Grassland/Savanna, Subsistence Agriculture | L15: Topsoil | M15: 129 samples across Limpopo National Park land uses/soil types | N15: NIR | O15: Standard NIR range (not further specified in available sources) | P15: NIR spectrometer | Q15: Not specified in available sources | R15: Air-dried, ground, sieved | S15: Laboratory | T15: Soil organic carbon (SOC); clay content used as covariate | U15: Standard SOC and clay content reference methods | V15: Not specified in available sources | W15: None specified | X15: PLSR, combining spectral NIR data with clay content as covariate | Y15: Cross-validation | Z15: R2=0.84, RMSE=0.28% for SOC; clay content covariate explained 32% of variance | AA15: Not specified in available sources | AB15: Land use, soil type, location within park | AC15: Restricted (regional LNP SSL) | AD15: Partial | AE15: Not specified in available sources | AF15: Not specified in available sources | AG15: Cost-efficient SOC estimation for conservation area/protected park management | AH15: Limited sample density in a poorly-accessible conservation area | AI15: Combine spectral data with auxiliary environmental covariates (e.g. clay content) to improve SOC prediction accuracy | AJ15: Combining NIR spectral data with clay content as a covariate in a PLSR model substantially improved SOC prediction (R2=0.84, RMSE=0.28%) for soils across the Limpopo National Park, Mozambique, demonstrating a cost-efficient approach for conservation-area soil monitoring. | AK15: Yes | AL15: Yes | AM15: Yes | AO15: =IF(AN15<>"","Exclude (duplicate)",IF(OR(AK15="Check",AL15="Check",AM15="Check"),"Check",IF(AND(AK15="Yes",AL15="Yes",AM15="Yes"),"Include","Exclude"))) -> Include | AQ15: Introduces | AR15: MZ-LNP | AT15: =IF(AR15="","",IFERROR(INDEX(Libraries!$B:$B,MATCH(AR15,Libraries!$A:$A,0)),"ID not found")) -> Limpopo National Park NIR library
A16: Safanelli J.L.; Hengl T.; Parente L.L.; Minarik R.; Bloom D.E.; Todd-Brown K.; Gholizadeh A.; de Sousa Mendes W.; Sanderman J. | B16: Open Soil Spectral Library (OSSL): Building reproducible soil calibration models through open development and community engagement | C16: 2025 | D16: 10.1371/journal.pone.0296545 | E16: OSSL | F16: Global | G16: NA | H16: EU, N & S America | I16: 135651 | J16: Global diversity covering KSSL, AfSIS, LUCAS, ISRIC, CAF | K16: Diverse/Global | L16: Variable (topsoil and subsoil), compiled from multiple contributing libraries | M16: Aggregated from multiple national/regional libraries (KSSL, AfSIS, LUCAS, ISRIC, CAF, etc.) | N16: VisNIR and MIR | O16: VisNIR ~350-2500; MIR ~2500-15000 (4000-600 cm-1) | P16: Multiple instruments harmonized across contributing labs | Q16: Varies by contributing lab/instrument | R16: Varies by source library (typically air-dried, ground, sieved) | S16: Laboratory (multiple labs) | T16: Wide range: SOC, texture, pH, CEC, nutrients, etc. | U16: Varies by contributing lab | V16: Harmonization pipeline (open-source R workflow) | W16: None specified as standard step | X16: Machine learning calibration models (open, reproducible pipeline) | Y16: Cross-validation within reproducible ML pipeline | Z16: R2, RMSE reported per property/model | AA16: Open development and community engagement for quality review | AB16: Location, source library, soil properties, instrument metadata | AC16: Open (public, reproducible, Zenodo-hosted) | AD16: High - explicitly designed for open, reproducible, FAIR data science | AE16: OSSL harmonization/standardization pipeline (soilspectroscopy.org) | AF16: Combines and harmonizes KSSL, AfSIS, LUCAS, ISRIC, CAF and other libraries into unified open dataset | AG16: Reproducible open soil calibration model development; community-driven soil spectroscopy | AH16: Spatial over-representation of USA/EU with limited data in Asia, South America, Australia | AI16: Expand geographic diversity; continued community engagement and contribution | AJ16: OSSL compiles ~91,600 MIR and ~65,000 VisNIR scans from multiple global libraries into an open, reproducible calibration and modeling resource, though it over-represents USA and EU soils relative to other continents. | AK16: Yes | AL16: Yes | AM16: Yes | AO16: =IF(AN16<>"","Exclude (duplicate)",IF(OR(AK16="Check",AL16="Check",AM16="Check"),"Check",IF(AND(AK16="Yes",AL16="Yes",AM16="Yes"),"Include","Exclude"))) -> Include | AQ16: Introduces | AR16: GL-OSSL | AT16: =IF(AR16="","",IFERROR(INDEX(Libraries!$B:$B,MATCH(AR16,Libraries!$A:$A,0)),"ID not found")) -> Open Soil Spectral Library (OSSL)
A17: van Leeuwen C.C.E.; Mulder V.L.; Heuvelink G.B.M. | B17: The effect of modeller's choices and measurement errors on the performance of MIR soil spectroscopy models | C17: 2026 | D17: 10.1016/j.geoderma.2026.117804 | E17: KSSL/LUCAS | F17: National | G17: Netherlands | H17: Europe | I17: 136 | J17: Netherlands soils and USA soils | K17: Diverse | AK17: Yes | AL17: Yes | AM17: Yes | AO17: =IF(AN17<>"","Exclude (duplicate)",IF(OR(AK17="Check",AL17="Check",AM17="Check"),"Check",IF(AND(AK17="Yes",AL17="Yes",AM17="Yes"),"Include","Exclude"))) -> Include | AP17: Library links taken from sheet ("KSSL/LUCAS") – check | AQ17: Methods for | AR17: US-KSSL-MIR | AS17: EU-LUCAS-VNIR | AT17: =IF(AR17="","",IFERROR(INDEX(Libraries!$B:$B,MATCH(AR17,Libraries!$A:$A,0)),"ID not found")) -> USDA NSSC-KSSL MIR library
A18: Santra P.; Singh R.; Sarathjith M.C.; Panwar N.R.; Varghese P.; Das B.S. | B18: Reflectance spectroscopic approach for estimation of soil properties in hot arid western Rajasthan, India | C18: 2015 | D18: 10.1007/s12665-015-4383-x | E18: India Regional | F18: Regional | G18: Western Rajasthan, India | H18: Asia | I18: 138 | J18: Hot arid surface soils | K18: Agricultural/Cropland, Grassland and Dunes | L18: Surface (hot arid soils) | M18: 138 soil samples from hot arid western Rajasthan compiled into a regional spectral library | N18: vis-NIR-SWIR | O18: 350-2500 | P18: vis-NIR-SWIR spectroradiometer | Q18: Not specified in available sources | R18: Air-dried, ground, sieved | S18: Laboratory | T18: Sand and clay content, and other basic soil properties | U18: Standard reference methods for texture and basic soil properties | V18: Derived band reflectance | W18: Principal components (PCs) and derived band reflectance | X18: Linear models using PCs/derived band reflectance; PLSR found even better than PC-based and band-reflectance models | Y18: Cross-validation | Z18: Sand and clay content satisfactorily estimated (R2/RMSE property-dependent) | AA18: Not specified in available sources | AB18: Location, arid land-use type | AC18: Restricted (regional Indian arid-zone SSL) | AD18: Partial | AE18: Not specified in available sources | AF18: Not specified in available sources | AG18: Rapid assessment of soil resources and land degradation monitoring in hot arid regions | AH18: Conventional soil sampling and lab analysis in hot arid tracts is a formidable, resource-intensive task | AI18: Use PLSR-based reflectance models for rapid soil resource assessment in arid regions; expand the arid-zone spectral library | AJ18: A 138-sample vis-NIR-SWIR spectral library for hot arid western Rajasthan enabled satisfactory estimation of sand and clay content, with PLSR models outperforming PC-based and band-reflectance approaches, supporting rapid soil resource assessment and land degradation monitoring in extreme arid environments. | AK18: Yes | AL18: Yes | AM18: Yes | AO18: =IF(AN18<>"","Exclude (duplicate)",IF(OR(AK18="Check",AL18="Check",AM18="Check"),"Check",IF(AND(AK18="Yes",AL18="Yes",AM18="Yes"),"Include","Exclude"))) -> Include | AQ18: Introduces | AR18: IN-RAJ | AT18: =IF(AR18="","",IFERROR(INDEX(Libraries!$B:$B,MATCH(AR18,Libraries!$A:$A,0)),"ID not found")) -> Western Rajasthan vis-NIR-SWIR library
A19: Makhamreh Z.; Kakish S.; Bani K.H. | B19: An Investigation of Soil Spectral Characteristics under Different Conditions in Jordan | C19: 2024 | D19: 10.52939/ijg.v20i6.3335 | E19: - | F19: National | G19: Jordan | H19: Asia | I19: 143 | J19: Typic Chromoxerets, Haploxeroils, Xerochreptic Calciorthids | K19: Forest and Agricultural/Cropland | L19: Surface (soil profile-linked sampling) | M19: Field sampling paired with soil profile description across northern Jordan | N19: vis-NIR-SWIR | O19: 350-2500 | P19: Field/laboratory spectroradiometer | Q19: Not specified in available sources | R19: Air-dried; chemical analysis via infrared cell in high-frequency induction oven | S19: Laboratory | T19: Iron oxides, organic carbon, inorganic carbon | U19: High-frequency induction oven infrared cell analysis; USDA soil classification/profile description | V19: Not specified in available sources | W19: None specified | X19: Feature-space grouping/classification by reflectance-property relationships (not machine-learning regression) | Y19: Not specified in available sources | Z19: Qualitative pattern classification (iron-affected, organic-carbon-affected, inorganic-carbon-affected soil groups) | AA19: Not specified in available sources | AB19: Soil profile description, USDA classification | AC19: Not specified in available sources | AD19: Not specified in available sources | AE19: Not specified in available sources | AF19: Not specified in available sources | AG19: Preliminary soil description/classification using spectroscopy instead of full traditional profile analysis | AH19: Distinguishing overlapping spectral influences of iron, organic and inorganic carbon under varying climatic conditions | AI19: Use soil spectroscopy as a rapid preliminary classification tool ahead of full traditional soil profiling | AJ19: Vis-NIR-SWIR reflectance (350-2500 nm) of northern Jordan soils correlated strongly with organic carbon (linked to clay/CEC) and inorganic carbon (linked to silt/carbonate content), supporting spectroscopy as a promising preliminary soil classification tool under varying climatic conditions. | AK19: Yes | AL19: Yes | AM19: No | AO19: =IF(AN19<>"","Exclude (duplicate)",IF(OR(AK19="Check",AL19="Check",AM19="Check"),"Check",IF(AND(AK19="Yes",AL19="Yes",AM19="Yes"),"Include","Exclude"))) -> Exclude | AP19: Spectral characterisation study (143 samples), no library | AQ19: — | AT19: =IF(AR19="","",IFERROR(INDEX(Libraries!$B:$B,MATCH(AR19,Libraries!$A:$A,0)),"ID not found"))
A20: Gholizadeh A.; Neumann C.; Chabrillat S.; van Wesemael B.; Castaldi F.; Borůvka L.; Sanderman J.; Klement A.; Hohmann C. | B20: Soil organic carbon estimation using VNIR–SWIR spectroscopy: The effect of multiple sensors and scanning conditions | C20: 2021 | D20: 10.1016/j.still.2021.105017 | E20: - | F20: Local | G20: Czech Republic | H20: Europe | I20: 143 | J20: Agricultural soils | K20: Agricultural/Arable | AK20: Yes | AL20: Yes | AM20: No | AO20: =IF(AN20<>"","Exclude (duplicate)",IF(OR(AK20="Check",AL20="Check",AM20="Check"),"Check",IF(AND(AK20="Yes",AL20="Yes",AM20="Yes"),"Include","Exclude"))) -> Exclude | AP20: Sensor-comparison study (143 samples), no library | AQ20: — | AT20: =IF(AR20="","",IFERROR(INDEX(Libraries!$B:$B,MATCH(AR20,Libraries!$A:$A,0)),"ID not found"))
A21: Clingensmith C.M.; Grunwald S. | B21: Predicting Soil Properties and Interpreting Vis-NIR Models from across Continental United States | C21: 2022 | D21: 10.3390/s22093187 | E21: KSSL | F21: National | G21: USA | H21: North America | I21: 14574 | J21: Alfisols, Andisols, Aridisols, Entisols, Gelisols, Histosols, Inceptisols, Mollisols, Spodosols, Ultisols, Vertisols | K21: Agricultural | L21: Multiple horizons (full pedon/profile data) | M21: 14574 samples extracted from NRCS-KSSL database (samples collected 2011-2015), fully described pedons across continental USA | N21: vis-NIR | O21: 350-2500 (ASD LabSpec 2500) | P21: ASD LabSpec 2500 vis-NIR spectrometer | Q21: Not specified in available sources | R21: Air-dried, ground, sieved (standardized NRCS methods) | S21: Laboratory | T21: Soil carbon, texture, and other pedological/analytical properties | U21: Standardized NRCS reference methods (with NRCS procedure codes) | V21: Not specified in available sources | W21: Wavelength importance analysis (e.g. ~2300-2400 nm associated with C-H bond combination vibrations) | X21: Chemometric and machine learning methods (including PLSR and Cubist) | Y21: Model comparison across approaches | Z21: R2/RMSE (property-dependent); wavelength importance attributed to functional groups | AA21: High-quality standardized/well-documented NRCS sample collection, preparation and analysis | AB21: Pedon site, soil layer/horizon, USDA soil order/suborder, NRCS procedure codes | AC21: Restricted (NRCS-KSSL database) | AD21: Partial | AE21: NRCS standardized soil sampling and analytical protocol | AF21: Not specified in available sources | AG21: Continental-scale soil property prediction and interpretation of important wavelengths/functional groups | AH21: Large, high-quality national spectral archives are underutilized; interpreting which wavelengths drive predictions | AI21: Combine chemometric/ML methods with wavelength-importance interpretation to make better use of the extensive NRCS-KSSL spectral archive | AJ21: Using ~14,574 samples from the NRCS-KSSL database across the continental USA, the study compared chemometric and machine learning models for vis-NIR soil property prediction and attributed important wavelengths (e.g. 2300-2400 nm) to specific functional groups (C-H bonds), demonstrating how to interpret as well as predict from a large national spectral library. | AK21: Yes | AL21: Yes | AM21: Yes | AO21: =IF(AN21<>"","Exclude (duplicate)",IF(OR(AK21="Check",AL21="Check",AM21="Check"),"Check",IF(AND(AK21="Yes",AL21="Yes",AM21="Yes"),"Include","Exclude"))) -> Include | AQ21: Uses | AR21: US-KSSL-VNIR | AT21: =IF(AR21="","",IFERROR(INDEX(Libraries!$B:$B,MATCH(AR21,Libraries!$A:$A,0)),"ID not found")) -> USDA NSSC-KSSL vis-NIR library
A22: Brodský L.; Klement A.; Penížek V.; Kodešová R.; Boruvka L. | B22: Building soil spectral library of the czech soils for quantitative digital soil mapping | C22: 2011 | D22: 10.17221/24/2011-swr | E22: Soil spectral library of the Czech soils (SSL-CZ) | F22: National | G22: Czech Republic | H22: Europe | I22: 150 | J22: Chernozem, Cambisol, Arenosol, Phaeozem, Luvisol, Vertisol, Fluvisol, Gleysol | K22: Agricultural/Arable | L22: Topsoil (multiple sites across Czech soil types) | M22: 150 samples covering major Czech soil types (Chernozem, Cambisol, Arenosol, Phaeozem, Luvisol, Vertisol, Fluvisol, Gleysol) | N22: vis-NIR | O22: 350-2500 (typical ASD-type range used in this study) | P22: ASD FieldSpec-type spectroradiometer | Q22: Not specified in available sources | R22: Air-dried, ground, sieved | S22: Laboratory | T22: Soil organic carbon and other basic soil properties (pH, texture, hydrolytic acidity, salinity) | U22: Standard Czech reference methods (per Klute 1996 / Rhoades 1996 procedures) | V22: Not specified in available sources | W22: None specified | X22: PLSR | Y22: Cross-validation | Z22: R2/RMSE (property-dependent, not further specified in available sources) | AA22: Not specified in available sources | AB22: Soil type/classification, site location | AC22: Restricted (SSL-CZ, national library) | AD22: Partial | AE22: Not specified in available sources | AF22: Not specified in available sources | AG22: Quantitative digital soil mapping (DSM) for Czech soils | AH22: Building a sufficiently diverse spectral archive representing major national soil types | AI22: Expand SSL-CZ sample size/diversity to support broader digital soil mapping applications | AJ22: Established one of the first Czech national vis-NIR soil spectral libraries (SSL-CZ, 150 samples across 8 major soil types), providing a foundation for quantitative digital soil mapping in the Czech Republic, with subsequent work building on it for SOC mapping uncertainty analysis. | AK22: Yes | AL22: Yes | AM22: Yes | AO22: =IF(AN22<>"","Exclude (duplicate)",IF(OR(AK22="Check",AL22="Check",AM22="Check"),"Check",IF(AND(AK22="Yes",AL22="Yes",AM22="Yes"),"Include","Exclude"))) -> Include | AQ22: Introduces | AR22: CZ-SSL | AT22: =IF(AR22="","",IFERROR(INDEX(Libraries!$B:$B,MATCH(AR22,Libraries!$A:$A,0)),"ID not found")) -> Soil spectral library of the Czech soils (SSL-CZ)
A23: Bae J.; Seo I.; Hyun J.; Park Y.; Jeong M.; Kim J.; et al. | B23: A spatially rich, temporally coherent soil spectral dataset for soil organic carbon estimation | C23: 2026 | D23: 10.1038/s41597-026-06546-3 | E23: G-SSL | F23: Regional | G23: South Korea | H23: Asia | I23: 1500 | J23: Topsoil across 11 land cover types | K23: Forest, Agricultural (Paddy, Upland, Orchard, Greenhouse), Urban Park, Grassland, Riparian | L23: 0-15 cm (topsoil) | M23: 1500 topsoil samples systematically collected across Gyeonggi Province, South Korea (2024), spanning 11 land cover types (forests, paddy/upland fields, orchards, greenhouses, urban parks, artificial grasslands, riparian zones, bare lands) | N23: NIR | O23: 1400-2500 | P23: NIR spectrometer (specific model not detailed in available sources) | Q23: Not specified in available sources | R23: Air-dried, ground, sieved (standard topsoil prep) | S23: Laboratory | T23: Soil organic carbon (SOC) | U23: Standard SOC reference method (dry combustion, on 712 calibration samples) | V23: Not specified in available sources | W23: None specified | X23: PLSR | Y23: 70:30 train-test split | Z23: R2=0.95, RMSE=0.39%, RPD=4.54 | AA23: Systematic spatially- and temporally-coherent sampling design across land cover types | AB23: Land cover type, sampling date/location (Gyeonggi Province) | AC23: Open (published dataset, Scientific Data journal) | AD23: High - openly published, designed as a methodological benchmark for other regions | AE23: Systematic province-wide sampling protocol across 11 land cover types | AF23: Not specified in available sources | AG23: Digital SOC mapping and climate-mitigation/land-management support for a heterogeneous provincial landscape | AH23: NIR predictive performance depends on calibration datasets with adequate spatiotemporal coverage | AI23: Use the G-SSL as a methodological benchmark for developing region-specific spectral libraries in other heterogeneous landscapes | AJ23: The newly published Gyeonggi Soil Spectral Library (G-SSL, 1,500 NIR topsoil samples across 11 land cover types in South Korea) achieved excellent SOC prediction accuracy (R2=0.95, RPD=4.54) using PLSR, establishing a spatially rich, temporally coherent regional library intended as a benchmark for digital SOC mapping in other heterogeneous landscapes. | AK23: Yes | AL23: Yes | AM23: Yes | AO23: =IF(AN23<>"","Exclude (duplicate)",IF(OR(AK23="Check",AL23="Check",AM23="Check"),"Check",IF(AND(AK23="Yes",AL23="Yes",AM23="Yes"),"Include","Exclude"))) -> Include | AQ23: Introduces | AR23: KR-GSSL | AT23: =IF(AR23="","",IFERROR(INDEX(Libraries!$B:$B,MATCH(AR23,Libraries!$A:$A,0)),"ID not found")) -> Gyeonggi Soil Spectral Library (G-SSL)
A24: Silva E.B.; Giasson É.; Dotto A.C.; Caten A.T.; Demattê J.A.M.; Bacic I.L.Z.; da Veiga M. | B24: A regional legacy soil dataset for prediction of sand and clay content with VIS-NIR-SWIR, in southern Brazil | C24: 2019 | D24: 10.1590/18069657rbcs20180174 | E24: BSSL | F24: Regional | G24: Southern Brazil | H24: South America | I24: 1534 | J24: Inceptisols, Entisols, Ultisols, Oxisols, Aquents | K24: Agricultural | L24: Topsoil | M24: Soil samples collected across Piauí State, Northeastern Brazil, for regional SSL construction | N24: vis-NIR-SWIR | O24: 1000-2500 (best results); full range also tested | P24: vis-NIR-SWIR spectroradiometer | Q24: Not specified in available sources | R24: Air-dried, ground, sieved | S24: Laboratory | T24: Soil organic carbon (SOC), pH, and other soil chemical/physical properties | U24: Standard Brazilian soil analysis reference methods | V24: Standard Normal Variate (SNV) among most promising; best overall results were without preprocessing for SOC and pH | W24: Testing full spectrum vs 1000-2500 nm subset | X24: Cubist (most accurate machine learning model tested) | Y24: Cross-validation | Z24: Cubist most accurate; SOC and pH predictions best without preprocessing; 1000-2500 nm subset promising despite sensor limitations | AA24: Not specified in available sources | AB24: Location within Piauí State | AC24: Restricted (regional Piauí SSL; related to BSSL national effort) | AD24: Partial | AE24: Not specified in available sources | AF24: Not specified in available sources | AG24: Rapid, cost-efficient, environmentally friendly soil chemical/physical analysis for Northeastern Brazil using machine learning | AH24: Traditional soil analyses are time-consuming and not cost- or environmentally-efficient; sensor range limitations | AI24: Use Cubist modelling with minimal preprocessing; explore the 1000-2500 nm range further despite sensor limitations | AJ24: Building a soil spectral library for Piauí State (Northeastern Brazil), Cubist was the most accurate machine learning model for predicting soil properties, with SOC and pH best predicted without spectral preprocessing, and the 1000-2500 nm subset showing promise despite sensor range limitations. | AK24: Yes | AL24: Yes | AM24: Yes | AO24: =IF(AN24<>"","Exclude (duplicate)",IF(OR(AK24="Check",AL24="Check",AM24="Check"),"Check",IF(AND(AK24="Yes",AL24="Yes",AM24="Yes"),"Include","Exclude"))) -> Include | AP24: Key Findings cell describes the Piauí library, not this paper – fix | AQ24: Introduces | AR24: BR-RS | AT24: =IF(AR24="","",IFERROR(INDEX(Libraries!$B:$B,MATCH(AR24,Libraries!$A:$A,0)),"ID not found")) -> Southern Brazil regional legacy soil spectral dataset
A25: Shi Z.; Wang Q.L.; Peng J.; Ji W.J.; Liu H.J.; Li X.; Viscarra Rossel R.A. | B25: Development of a national VNIR soil-spectral library for soil classification and prediction of organic matter concentrations | C25: 2014 | D25: 10.1007/s11430-013-4808-x | E25: Chinese national VNIR soil-spectral library | F25: Continental | G25: China | H25: Asia | I25: 1581 | J25: Meadow, Paddy, Black soils, Chernozems, Red earth, Laterite, skeletal soils | K25: Agricultural, Meadow and Forest | L25: Topsoil | M25: 1581 samples across 14 provinces representing 16 soil groups of the Genetic Soil Classification of China | N25: vis-NIR | O25: 350-2500 | P25: Portable vis-NIR spectrometer | Q25: Not specified in available sources | R25: Air-dried, sieved | S25: Laboratory | T25: Soil organic matter (OM), soil classification/type | U25: Standard Chinese soil reference methods | V25: Savitzky-Golay smoothing with first derivative | W25: PCA (principal components analysis) | X25: Fuzzy k-means classification; PLSR for OM prediction | Y25: Cross-validation | Z25: R2, classification accuracy/kappa | AA25: Not specified in available sources | AB25: Province, Genetic Soil Classification group | AC25: Restricted (Chinese Soil Spectral Library, CSSL) | AD25: Partial | AE25: Not specified in available sources | AF25: Compilation across 14 provinces into single national library | AG25: National soil classification and organic matter concentration mapping | AH25: High diversity of soil types across a large territory complicating generic calibration | AI25: Stratified/spatially-constrained local modelling approaches (used in later CSSL papers) | AJ25: Established the first Chinese national vis-NIR soil spectral library (1,581 samples, 16 soil groups across 14 provinces), demonstrating feasibility of spectral soil classification and organic matter prediction at national scale. | AK25: Yes | AL25: Yes | AM25: Yes | AO25: =IF(AN25<>"","Exclude (duplicate)",IF(OR(AK25="Check",AL25="Check",AM25="Check"),"Check",IF(AND(AK25="Yes",AL25="Yes",AM25="Yes"),"Include","Exclude"))) -> Include | AQ25: Introduces | AR25: CN-CSSL | AT25: =IF(AR25="","",IFERROR(INDEX(Libraries!$B:$B,MATCH(AR25,Libraries!$A:$A,0)),"ID not found")) -> Chinese Soil Spectral Library (CSSL)
A26: Metzger K.; Zhang C.; Daly K. | B26: From benchtop to handheld MIR for soil analysis: Predicting lime requirement and organic matter in agricultural soils | C26: 2021 | D26: 10.1016/j.biosystemseng.2021.01.025 | E26: Republic of Ireland benchtop MIR library | F26: National | G26: Ireland | H26: Europe | I26: 160 | J26: Luvisols, Brown Earths, USDA textures: sandy loam, loam, clay loam | K26: Agricultural/Arable | L26: Topsoil (agricultural) | M26: 160 samples used to compare benchtop and handheld MIR instruments, including field-moist samples | N26: MIR (DRIFTS) | O26: MIR range; wavenumbers below 1300 cm-1 found less affected by water absorption | P26: Bench-top FTIR (DRIFTS) vs handheld/portable MIR spectrometer | Q26: Not specified in available sources | R26: Comparison of dried/ground samples (benchtop) vs field-moist samples (handheld) | S26: Laboratory (benchtop) and field-moist (handheld) conditions compared | T26: Lime requirement (LR), organic matter (OM) | U26: Standard lime requirement/base neutralizing capacity and organic matter reference methods | V26: Moisture correction; focus on wavenumbers below 1300 cm-1 less impacted by water absorption | W26: Selection of water-insensitive spectral regions (below 1300 cm-1) | X26: PLSR and machine learning models comparing benchtop vs handheld spectra | Y26: Cross-validation; benchtop vs handheld comparison | Z26: R2/RMSE (property-dependent); handheld predictions degraded by soil moisture but improved using water-insensitive wavenumber regions | AA26: Moisture-effect correction; compatibility check with existing spectral libraries/calibrations | AB26: Instrument type, moisture status of sample | AC26: Restricted (Irish research dataset) | AD26: Partial | AE26: Not specified in available sources | AF26: Identifying wavenumber regions compatible across benchtop and handheld MIR instruments to enable calibration transfer | AG26: Field-deployable MIR-based lime requirement and organic matter prediction using handheld instruments | AH26: Soil water content in field-moist samples obscures spectral signal, reducing handheld MIR prediction accuracy; compatibility with existing benchtop-derived calibrations | AI26: Focus predictive models on water-insensitive MIR wavenumber regions (<1300 cm-1) to improve handheld/field-moist sample performance | AJ26: Comparing benchtop and handheld MIR spectrometers for predicting lime requirement and organic matter in Irish agricultural soils, the study found that soil moisture degraded handheld/field predictions, but that focusing on wavenumbers below 1300 cm-1 (less water-sensitive) improved compatibility between handheld field measurements and benchtop-based calibrations. | AK26: Yes | AL26: Yes | AM26: No | AO26: =IF(AN26<>"","Exclude (duplicate)",IF(OR(AK26="Check",AL26="Check",AM26="Check"),"Check",IF(AND(AK26="Yes",AL26="Yes",AM26="Yes"),"Include","Exclude"))) -> Exclude | AP26: Benchtop vs handheld calibration (160 samples), not presented as a library | AQ26: — | AT26: =IF(AR26="","",IFERROR(INDEX(Libraries!$B:$B,MATCH(AR26,Libraries!$A:$A,0)),"ID not found"))
A27: Ng W.; Husnain; Anggria L.; Siregar A.F.; Hartatik W.; Sulaeman Y.; Jones E.; Minasny B. | B27: Developing a soil spectral library using a low-cost NIR spectrometer for precision fertilization in Indonesia | C27: 2020 | D27: 10.1016/j.geodrs.2020.e00319 | E27: Indonesian Soil Spectral Library | F27: National | G27: Indonesia | H27: Asia | I27: 1601 | J27: Volcanic soils | K27: Agricultural | L27: Topsoil (agricultural) | M27: 1601 samples from Indonesian volcanic-influenced agricultural soils, linked to field fertilizer trials | N27: NIR | O27: 1300-2600 | P27: NeoSpectra miniature/low-cost NIR spectrometer | Q27: Not specified in available sources | R27: Air-dried, ground, sieved | S27: Laboratory | T27: Soil texture, pH, carbon, soil nutrients (N, P, K) | U27: Standard Indonesian soil fertility reference methods | V27: Not specified in available sources | W27: None specified | X27: PLSR regression models plus categorical models for nutrient-level classification; Mitscherlich-Bray (MB) equations for fertilizer recommendation | Y27: Cross-validation | Z27: Mixed accuracy; e.g. pH R2 approx 0.52-0.60 depending on study/spectrometer | AA27: Not specified in available sources | AB27: Crop type, location, fertilizer trial data | AC27: Restricted (Indonesian agricultural ministry-linked dataset) | AD27: Partial | AE27: Not specified in available sources | AF27: Not specified in available sources | AG27: Precision fertilization recommendations for food crops using low-cost NIR spectroscopy | AH27: Miniature/low-cost NIR spectrometers show mixed, sometimes lower accuracy (e.g. for pH) compared to lab-grade spectrometers | AI27: Apply correction factors and further testing of low-cost SWIR/NIR spectrometer configurations to improve fertilizer recommendation accuracy | AJ27: A soil spectral library built with a low-cost NeoSpectra NIR spectrometer (1300-2600 nm) enabled fertilizer nutrient-level classification and Mitscherlich-Bray-based fertilizer recommendations for Indonesian food crops, though prediction accuracy for some properties (e.g. pH) was more modest than with laboratory-grade instruments. | AK27: Yes | AL27: Yes | AM27: Yes | AO27: =IF(AN27<>"","Exclude (duplicate)",IF(OR(AK27="Check",AL27="Check",AM27="Check"),"Check",IF(AND(AK27="Yes",AL27="Yes",AM27="Yes"),"Include","Exclude"))) -> Include | AQ27: Introduces | AR27: ID-ISSL | AT27: =IF(AR27="","",IFERROR(INDEX(Libraries!$B:$B,MATCH(AR27,Libraries!$A:$A,0)),"ID not found")) -> Indonesian Soil Spectral Library
A28: Novais J.J.M.; Rosin N.A.; Rosas J.T.F.; Poppiel R.R.; Dotto A.C.; Paiva A.F.S.; Bellinaso H.; Albarracín H.S.R.; Amorim M.T.A.; dos Bartsch B.A.; Vogel L.G.; Mello D.C.; Francelino M.R.; Alves M.R.; Falcioni R.; Demattê J.A.M. | B28: The Brazilian Soil Spectral Library data opening | C28: 2024 | D28: 10.19047/0136-1694-2024-119-261-305 | E28: BSSL | F28: National | G28: Brazil | H28: South America | I28: 16084 | J28: Tropical Soils | K28: Agriculture/Pasture and Forest | AK28: Yes | AL28: Yes | AM28: Yes | AO28: =IF(AN28<>"","Exclude (duplicate)",IF(OR(AK28="Check",AL28="Check",AM28="Check"),"Check",IF(AND(AK28="Yes",AL28="Yes",AM28="Yes"),"Include","Exclude"))) -> Include | AQ28: Extends / updates | AR28: BR-BSSL | AT28: =IF(AR28="","",IFERROR(INDEX(Libraries!$B:$B,MATCH(AR28,Libraries!$A:$A,0)),"ID not found")) -> Brazilian Soil Spectral Library (BSSL, vis-NIR-SWIR)
A29: Rizzo R.; Demattê J.A.M.; Lepsch I.F.; Gallo B.C.; Fongaro C.T. | B29: Digital soil mapping at local scale using a multi-depth Vis-NIR spectral library and terrain attributes | C29: 2016 | D29: 10.1016/j.geoderma.2016.03.019 | E29: Multi-depth Vis-NIR spectral library (SRSSL) | F29: Local | G29: Brazil | H29: South America | I29: 162 | J29: Cambissolos, Latossolos, Nitossolos, Argissolos, Neossolos | K29: Agricultural | L29: Multi-depth (topsoil and subsoil profiles) | M29: 162 sample locations on a 270-ha farm in Piracicaba, São Paulo, Brazil; combined with regional spectral library and terrain attributes | N29: vis-NIR | O29: 350-2500 | P29: ASD FieldSpec-type spectroradiometer | Q29: Not specified in available sources | R29: Air-dried, ground, sieved | S29: Laboratory | T29: Soil type/class (for digital soil mapping) | U29: Standard reference methods supporting soil classification | V29: Not specified in available sources | W29: Terrain attributes combined with spectral data as covariates | X29: Digital soil mapping combining local Vis-NIR spectra, a regional spectral library, and terrain attributes | Y29: Cross-validation; accuracy assessment by landscape position/soil class | Z29: Lower classification accuracy for soils in lower landscape positions and for Cambisols | AA29: Not specified in available sources | AB29: Terrain attributes, landscape position, farm location | AC29: Restricted (regional Brazilian SSL - SRSSL) | AD29: Partial | AE29: Not specified in available sources | AF29: Combines local samples with a regional spectral library to extend training data for local DSM | AG29: Local-scale digital soil mapping (DSM) for farm-level soil classification | AH29: Reduced accuracy for soils at lower landscape positions and certain soil classes (Cambisols) | AI29: Combine spectral libraries with terrain attributes to improve local DSM, particularly further addressing lower-landscape-position soils | AJ29: Combining local Vis-NIR spectra, a regional Brazilian spectral library, and terrain attributes produced an effective farm-scale (270 ha) digital soil map in Piracicaba, Brazil, though accuracy was lower for soils in lower landscape positions and for Cambisols. | AK29: Yes | AL29: Yes | AM29: Yes | AO29: =IF(AN29<>"","Exclude (duplicate)",IF(OR(AK29="Check",AL29="Check",AM29="Check"),"Check",IF(AND(AK29="Yes",AL29="Yes",AM29="Yes"),"Include","Exclude"))) -> Include | AP29: Regional Brazilian library assumed to be BSSL – check | AQ29: Uses | AR29: BR-BSSL | AT29: =IF(AR29="","",IFERROR(INDEX(Libraries!$B:$B,MATCH(AR29,Libraries!$A:$A,0)),"ID not found")) -> Brazilian Soil Spectral Library (BSSL, vis-NIR-SWIR)
